Workbook
Name Cost_of_debt: WACC!$C$17
Name Cost_of_equity: WACC!$C$10
Name Debt_weight: WACC!$C$26
Name Equity_Risk_Premium: WACC!$C$8
Name Equity_weight: WACC!$C$25
Name Levered_Beta: WACC!$C$9
Name pretax_cost_of_debt: WACC!$C$15
Name Risk_Free_Rate: WACC!$C$7
Name spread: WACC!$D$15
Name tax_rate: WACC!$C$16

Sheet Summary
A4: DCF Valuation of AVENUE SUPERMARTS LTD( DMART)
A7: DCF calculation
A8: WACC calculation
A9: Historical Financial statements and growth
A15: Prepared by: Jyoti Barik

Sheet DCF
A1: DCF Valuation of AVENUE SUPERMARTS LTD( DMART) | J1: Historical | T1: Forecast
B2: Calculation of Free cash flow(Consolidated Figures in Rs. Crores) | I2: Details | J2: 42430 | K2: 42795 | L2: 43160 | M2: 43525 | N2: 43891 | O2: 44256 | P2: 44621 | Q2: 44986 | R2: 45352 | S2: 45717 | T2: 46112 | U2: 46477 | V2: 46843 | W2: 47208 | X2: 47573
B3: Actual | C3: Forecast | I3: Depreciation | J3: 98.43 | K3: 127.82 | L3: 159 | M3: 212.49 | N3: 374.41 | O3: 414.16 | P3: 498.08 | Q3: 638.87 | R3: 730.76 | S3: 869.52 | T3: =T4*$J$7 -> 1071.4202 | U3: =U4*$J$7 -> 1318.553 | V3: =V4*$J$7 -> 1622.6891 | W3: =W4*$J$7 -> 1996.977 | X3: =X4*$J$7 -> 2457.5978
A4: Year | B4: 45747 | C4: 46112 | D4: 46477 | E4: 46843 | F4: 47208 | G4: 47573 | I4: Net Block | J4: 2094 | K4: 2577 | L4: 3400 | M4: 4401 | N4: 5948 | O4: 7009 | P4: 9260 | Q4: 11340 | R4: 13415 | S4: 16206 | T4: =S4*(1+$J$8) -> 19944.06 | U4: =T4*(1+$J$8) -> 24544.338 | V4: =U4*(1+$J$8) -> 30205.711 | W4: =V4*(1+$J$8) -> 37172.93 | X4: =W4*(1+$J$8) -> 45747.202
C5: 0.5 | D5: =C5+1 -> 1.5 | E5: =D5+1 -> 2.5 | F5: =E5+1 -> 3.5 | G5: =F5+1 -> 4.5 | I5: Growth % in Net block | K5: =K4/J4-1 -> 0.23065903 | L5: =L4/K4-1 -> 0.3193636 | M5: =M4/L4-1 -> 0.29441176 | N5: =N4/M4-1 -> 0.35151102 | O5: =O4/N4-1 -> 0.17837929 | P5: =P4/O4-1 -> 0.32115851 | Q5: =Q4/P4-1 -> 0.22462203 | R5: =R4/Q4-1 -> 0.1829806 | S5: =S4/R4-1 -> 0.20805069
A6: Growth %(assumption based on past 10 years growth rate) | C6: 0.25 | D6: 0.22 | E6: 0.2 | F6: 0.18 | G6: 0.17 | I6: Depn as a % of Net block | J6: =J3/J4 -> 0.047005731 | K6: =K3/K4 -> 0.04960031 | L6: =L3/L4 -> 0.046764706 | M6: =M3/M4 -> 0.048282209 | N6: =N3/N4 -> 0.062947209 | O6: =O3/O4 -> 0.059089742 | P6: =P3/P4 -> 0.053788337 | Q6: =Q3/Q4 -> 0.056337743 | ... S6: =S3/S4 -> 0.053654202
A7: Sales | B7: ='Historical fin satements'!K4 -> 59358 | C7: =B7*(1+C6) -> 74197.5 | D7: =C7*(1+D6) -> 90520.95 | E7: =D7*(1+E6) -> 108625.14 | F7: =E7*(1+F6) -> 128177.67 | G7: =F7*(1+G6) -> 149967.87 | I7: Median-Depn as % of net block | J7: =MEDIAN(J6:S6) -> 0.05372127
A8: EBIDTA | B8: ='Historical fin satements'!K12 -> 4494.46 | C8: =C7*7.5% -> 5564.8125 | D8: =D7*8% -> 7241.676 | E8: =E7*8% -> 8690.0112 | F8: =F7*8% -> 10254.213 | G8: =G7*8% -> 11997.429 | I8: Median-growth % Net block | J8: =MEDIAN(K5:S5) -> 0.23065903
A9: Less: Depreciation (assumption based on percent of net block) | B9: ='Historical fin satements'!K14 -> 869.52 | C9: =T3 -> 1071.4202 | D9: =U3 -> 1318.553 | E9: =V3 -> 1622.6891 | F9: =W3 -> 1996.977 | G9: =X3 -> 2457.5978
A10: EBIT | B10: =B8-B9 -> 3624.94 | C10: =C8-C9 -> 4493.3923 | D10: =D8-D9 -> 5923.123 | E10: =E8-E9 -> 7067.3221 | F10: =F8-F9 -> 8257.2362 | G10: =G8-G9 -> 9539.8317 | I10: Working capital changes | J10: -69 | K10: -270 | L10: -243 | M10: -351 | N10: -376 | O10: -127 | P10: -582 | Q10: -320 | R10: -644 | S10: -1113
A11: Less: Tax (26%) | B11: =26%*B10 -> 942.4844 | C11: =26%*C10 -> 1168.282 | D11: =26%*D10 -> 1540.012 | E11: =26%*E10 -> 1837.5037 | F11: =26%*F10 -> 2146.8814 | G11: =26%*G10 -> 2480.3562 | I11: Sales | J11: 8584 | K11: 11898 | L11: 15033 | M11: 20005 | N11: 24870 | O11: 24143 | P11: 30976 | Q11: 42840 | R11: 50789 | S11: 59358
A12: NOPAT | B12: =B10-B11 -> 2682.4556 | C12: =C10-C11 -> 3325.1103 | D12: =D10-D11 -> 4383.111 | E12: =E10-E11 -> 5229.8183 | F12: =F10-F11 -> 6110.3548 | G12: =G10-G11 -> 7059.4754 | I12: WC as a % of Sales | J12: =J10/J11 -> -0.0080382106 | K12: =K10/K11 -> -0.02269289 | L12: =L10/L11 -> -0.016164438 | M12: =M10/M11 -> -0.017545614 | N12: =N10/N11 -> -0.015118617 | O12: =O10/O11 -> -0.0052603239 | P12: =P10/P11 -> -0.01878874 | Q12: =Q10/Q11 -> -0.0074696545 | ... S12: =S10/S11 -> -0.018750632
A13: Add : Depreciation | B13: =B9 -> 869.52 | C13: =C9 -> 1071.4202 | D13: =D9 -> 1318.553 | E13: =E9 -> 1622.6891 | F13: =F9 -> 1996.977 | G13: =G9 -> 2457.5978 | I13: Median | J13: =-MEDIAN(J12:S12) -> 0.015641528
A14: Cash NOPAT | B14: =B12+B13 -> 3551.9756 | C14: =C12+C13 -> 4396.5305 | D14: =D12+D13 -> 5701.664 | E14: =E12+E13 -> 6852.5075 | F14: =F12+F13 -> 8107.3318 | G14: =G12+G13 -> 9517.0732
A15: Less: Capex & Changes in WC | B15: =S18-S10 -> 4542 | C15: =C14*80% -> 3517.2244 | D15: =D14*80% -> 4561.3312 | E15: =E14*70% -> 4796.7552 | F15: =F14*50% -> 4053.6659 | G15: =G14*50% -> 4758.5366 | J15: Historical
A16: (assumption based on percent of NOPAT) | J16: 42430 | K16: 42795 | L16: 43160 | M16: 43525 | N16: 43891 | O16: 44256 | P16: 44621 | Q16: 44986 | R16: 45352 | S16: 45717
A17: FCFF | B17: =B14-B15 -> -990.0244 | C17: =C14-C15 -> 879.3061 | D17: =D14-D15 -> 1140.3328 | E17: =E14-E15 -> 2055.7522 | F17: =F14-F15 -> 4053.6659 | G17: =G14-G15 -> 4758.5366 | I17: Sales | J17: 8583.76 | K17: 11897.7 | L17: 15033.2 | M17: 20004.52 | N17: 24870.2 | O17: 24143.06 | P17: 30976.27 | Q17: 42839.56 | R17: 50788.83 | S17: 59358.05
A18: Discounting rate(WACC) | C18: =$B$22 -> 0.1174 | D18: =$B$22 -> 0.1174 | E18: =$B$22 -> 0.1174 | F18: =$B$22 -> 0.1174 | G18: =$B$22 -> 0.1174 | I18: Capex | J18: =-'Raw cashflow'!D14+'Raw cashflow'!D15 -> 2 | K18: =-'Raw cashflow'!E14+'Raw cashflow'!E15 -> 655 | L18: =-'Raw cashflow'!F14+'Raw cashflow'!F15 -> 923 | M18: =-'Raw cashflow'!G14+'Raw cashflow'!G15 -> 1425 | N18: =-'Raw cashflow'!H14+'Raw cashflow'!H15 -> 1718 | O18: =-'Raw cashflow'!I14+'Raw cashflow'!I15 -> 2031 | P18: =-'Raw cashflow'!J14+'Raw cashflow'!J15 -> 2431 | Q18: =-'Raw cashflow'!K14+'Raw cashflow'!K15 -> 2217 | ... S18: =-'Raw cashflow'!M14+'Raw cashflow'!M15 -> 3429
A19: PV of Free Cash flow [FCFF/(1+WACC)^n] | C19: =C17/(1+C18)^C5 -> 831.83225 | D19: =D17/(1+D18)^D5 -> 965.42517 | E19: =E17/(1+E18)^E5 -> 1557.5755 | F19: =F17/(1+F18)^F5 -> 2748.6384 | G19: =G17/(1+G18)^G5 -> 2887.5826 | I19: % of Sales | J19: =J18/J17 -> 0.00023299813 | K19: =K18/K17 -> 0.055052657 | L19: =L18/L17 -> 0.06139744 | M19: =M18/M17 -> 0.071233901 | N19: =N18/N17 -> 0.069078656 | O19: =O18/O17 -> 0.084123554 | P19: =P18/P17 -> 0.07847943 | Q19: =Q18/Q17 -> 0.051751232 | ... S19: =S18/S17 -> 0.05776807
A20: PV of FCFF | B20: =SUM(C19:G19) -> 8991.0539 | J20: =MEDIAN(K19:S19) -> 0.06139744
A22: WACC | B22: =ROUND(WACC!C29,4) -> 0.1174
A23: Terminal growth rate (g) | B23: 0.065 | C23: Considering India's GDP growth
A25: Terminal Value
A26: 5th Year FCF*(1+g) | B26: =G17*(1+B23) -> 5067.8415 | C26: FCFF of Mar-30*(1+terminal growth rate) | I26: Sensitivity Analysis
A27: Terminal value (TV) | B27: =B26/(B22-B23) -> 96714.532 | C27: FCF for Mar-30 * (1+g) / (WACC - g) | I27: =B27 -> 96714.532 | J27: 0.09 | K27: 0.1 | L27: 0.1174 | M27: 0.14 | N27: 0.15 | O27: WACC
H28: Growth rate | I28: 0.04 | J28: 98977.562 | K28: 82481.301 | L28: 63938.993 | M28: 49488.781 | N28: 44989.801
A29: PV of Terminal value | B29: =B27/(1+B22)^DCF!G5 -> 58688.463 | C29: TV/(1+WACC)^no. of years in forecast period | I29: 0.05 | J29: 124911.59 | K29: 99929.269 | L29: 74131.505 | M29: 55516.26 | N29: 49964.634
I30: 0.065 | J30: 202713.66 | K30: 144795.47 | L30: 96714.532 | M30: 67571.22 | N30: 59621.665
A31: Enterprise Value | B31: =B29+B20 -> 67679.517 | C31: PV of all FCFF + PV of Terminal value | I31: 0.07 | J31: 254581.71 | K31: 169721.14 | L31: 107418.44 | M31: 72737.631 | N31: 63645.427
I32: 0.08 | J32: 513921.95 | K32: 256960.98 | L32: 137412.29 | M32: 85653.659 | N32: 73417.422
A33: Enterprise value | B33: =B31 -> 67679.517
A34: Add: cash | B34: ='Raw BS'!M37 -> 358
A35: Less: Debt | B35: ='Raw BS'!M9 -> 820
A36: Intrinsic value | B36: =B33+B34-B35 -> 67217.517
A38: Outstanding shares | B38: ='Data sheet'!B6 -> 65.20883
A39: Equity Value per Share | B39: =B36/B38 -> 1030.8039
A41: Current Price (Market) | B41: ='Data sheet'!B8 -> 4530 | C41: As on 30 Apr 2026
A42: Premium | B42: =B41/B39 -> 4.3946283

Sheet WACC
B1: AVENUE SUPERMARTS LTD( DMART)
B3: Calculation of discount rate (WACC)
B5: Cost of equity
B7: Risk Free Rate | C7: 0.06961 | E7: https://in.investing.com/rates-bonds/india-10-year-bond-yield-historical-data
B8: Equity Risk Premium | C8: 0.0708 | E8: https://pages.stern.nyu.edu/~adamodar/
B9: Levered Beta | C9: 0.68 | E9: https://www.moneycontrol.com/india/stockpricequote/retail/avenuesupermarts/AS19
B10: Cost of Equity (Ke) | C10: =Risk_Free_Rate+(Equity_Risk_Premium*Levered_Beta) -> 0.117754
B11: =Risk_Free_Rate+(Equity_Risk_Premium*Levered_Beta)'
B13: Cost of debt
B15: Pre-tax Cost of Debt(Risk free rate + Spread) | C15: =Risk_Free_Rate+spread -> 0.07661 | D15: 0.007 | E15: https://pages.stern.nyu.edu/~adamodar/ | I15: Spread
B16: Tax Rate | C16: 0.3
B17: After Tax Cost of Debt(Kd) | C17: =pretax_cost_of_debt*(1-tax_rate) -> 0.053627
B18: =pretax_cost_of_debt*(1-tax_rate)'
B20: Capital Structure | C20: (Amount in Cr.)
B21: Total Equity | C21: ='Data sheet'!B9 -> 295396 | E21: https://www.screener.in/company/DMART/consolidated/
B22: Total Debt | C22: 1609.19 | E22: https://www.screener.in/company/DMART/consolidated/
C23: =C22+C21 -> 297005.19
B25: Equity Weight | C25: =C21/$C$23 -> 0.99458195
B26: Debt Weight | C26: =C22/$C$23 -> 0.0054180535
B29: Weighted Average Cost of Capital (discount rate) | C29: =(Cost_of_equity*Equity_weight)+(Cost_of_debt*Debt_weight) -> 0.11740656
B30: =(Cost_of_equity*Equity_weight)+(Cost_of_debt*Debt_weight)'

Sheet Historical fin satements
A1: AVENUE SUPERMARTS LTD(Consolidated Figures in Rs. Crores)
E2: Income statement
A3: Narration | B3: 42460 | C3: 42825 | D3: 43190 | E3: 43555 | F3: 43921 | G3: 44286 | H3: 44651 | I3: 45016 | J3: 45382 | K3: 45747
A4: Sales | B4: 8584 | C4: 11898 | D4: 15033 | E4: 20005 | F4: 24870 | G4: 24143 | H4: 30976 | I4: 42840 | J4: 50789 | K4: 59358
A5: Sales Growth % | C5: =C4/B4-1 -> 0.3860671 | D5: =D4/C4-1 -> 0.26348966 | E5: =E4/D4-1 -> 0.33073904 | F5: =F4/E4-1 -> 0.2431892 | G5: =G4/F4-1 -> -0.029232006 | H5: =H4/G4-1 -> 0.28302199 | I5: =I4/H4-1 -> 0.3830062 | J5: =J4/I4-1 -> 0.18555089 | K5: =K4/J4-1 -> 0.16871764
A6: COGS | B6: =SUM('Data sheet'!B15,-'Data sheet'!B16,'Data sheet'!B17:B18) -> 7624.14 | C6: =SUM('Data sheet'!C15,-'Data sheet'!C16,'Data sheet'!C17:C18) -> 10513.34 | D6: =SUM('Data sheet'!D15,-'Data sheet'!D16,'Data sheet'!D17:D18) -> 13130.62 | E6: =SUM('Data sheet'!E15,-'Data sheet'!E16,'Data sheet'!E17:E18) -> 17653.36 | F6: =SUM('Data sheet'!F15,-'Data sheet'!F16,'Data sheet'!F17:F18) -> 21937.13 | G6: =SUM('Data sheet'!G15,-'Data sheet'!G16,'Data sheet'!G17:G18) -> 21475.31 | H6: =SUM('Data sheet'!H15,-'Data sheet'!H16,'Data sheet'!H17:H18) -> 27411.1 | I6: =SUM('Data sheet'!I15,-'Data sheet'!I16,'Data sheet'!I17:I18) -> 37815.13 | ... K6: =SUM('Data sheet'!K15,-'Data sheet'!K16,'Data sheet'!K17:K18) -> 52751.3
A7: % of Sales | B7: =B6/B4 -> 0.88818034 | C7: =C6/C4 -> 0.88362246 | D7: =D6/D4 -> 0.87345307 | E7: =E6/E4 -> 0.88244739 | F7: =F6/F4 -> 0.88207197 | G7: =G6/G4 -> 0.88950462 | H7: =H6/H4 -> 0.88491413 | I7: =I6/I4 -> 0.88270612 | ... K7: =K6/K4 -> 0.8886974
A8: Gross Profit | B8: =B4-B6 -> 959.86 | C8: =C4-C6 -> 1384.66 | D8: =D4-D6 -> 1902.38 | E8: =E4-E6 -> 2351.64 | F8: =F4-F6 -> 2932.87 | G8: =G4-G6 -> 2667.69 | H8: =H4-H6 -> 3564.9 | I8: =I4-I6 -> 5024.87 | ... K8: =K4-K6 -> 6606.7
A9: % of Sales | B9: =B8/B4 -> 0.11181966 | C9: =C8/C4 -> 0.11637754 | D9: =D8/D4 -> 0.12654693 | E9: =E8/E4 -> 0.11755261 | F9: =F8/F4 -> 0.11792803 | G9: =G8/G4 -> 0.11049538 | H9: =H8/H4 -> 0.11508587 | I9: =I8/I4 -> 0.11729388 | ... K9: =K8/K4 -> 0.1113026
A10: Operating Expense | B10: =SUM('Data sheet'!B19:B21) -> 295.16 | C10: =SUM('Data sheet'!C19:C21) -> 415.18 | D10: =SUM('Data sheet'!D19:D21) -> 549.72 | E10: =SUM('Data sheet'!E19:E21) -> 717.85 | F10: =SUM('Data sheet'!F19:F21) -> 804.76 | G10: =SUM('Data sheet'!G19:G21) -> 922.92 | H10: =SUM('Data sheet'!H19:H21) -> 1062.82 | I10: =SUM('Data sheet'!I19:I21) -> 1385.66 | ... K10: =SUM('Data sheet'!K19:K21) -> 2112.24
A11: % of Sales | B11: =B10/B4 -> 0.034384902 | C11: =C10/C4 -> 0.03489494 | D11: =D10/D4 -> 0.036567551 | E11: =E10/E4 -> 0.035883529 | F11: =F10/F4 -> 0.032358665 | G11: =G10/G4 -> 0.038227229 | H11: =H10/H4 -> 0.03431108 | I11: =I10/I4 -> 0.032345005 | ... K11: =K10/K4 -> 0.035584757
A12: EBITDA | B12: =B8-B10 -> 664.7 | C12: =C8-C10 -> 969.48 | D12: =D8-D10 -> 1352.66 | E12: =E8-E10 -> 1633.79 | F12: =F8-F10 -> 2128.11 | G12: =G8-G10 -> 1744.77 | H12: =H8-H10 -> 2502.08 | I12: =I8-I10 -> 3639.21 | ... K12: =K8-K10 -> 4494.46
A13: % of Sales | B13: =B12/B4 -> 0.077434762 | C13: =C12/C4 -> 0.081482602 | D13: =D12/D4 -> 0.089979379 | E13: =E12/E4 -> 0.081669083 | F13: =F12/F4 -> 0.085569361 | G13: =G12/G4 -> 0.072268152 | H13: =H12/H4 -> 0.080774793 | I13: =I12/I4 -> 0.08494888 | ... K13: =K12/K4 -> 0.075717848
A14: Depreciation | B14: ='Data sheet'!B23 -> 98.43 | C14: ='Data sheet'!C23 -> 127.82 | D14: ='Data sheet'!D23 -> 159 | E14: ='Data sheet'!E23 -> 212.49 | F14: ='Data sheet'!F23 -> 374.41 | G14: ='Data sheet'!G23 -> 414.16 | H14: ='Data sheet'!H23 -> 498.08 | I14: ='Data sheet'!I23 -> 638.87 | ... K14: ='Data sheet'!K23 -> 869.52
A15: % of Sales | B15: =B14/B4 -> 0.011466682 | C15: =C14/C4 -> 0.010742982 | D15: =D14/D4 -> 0.010576731 | E15: =E14/E4 -> 0.010621845 | F15: =F14/F4 -> 0.015054684 | G15: =G14/G4 -> 0.017154455 | H15: =H14/H4 -> 0.016079545 | I15: =I14/I4 -> 0.014912932 | ... K15: =K14/K4 -> 0.014648742
A16: EBIT | B16: =B12-B14 -> 566.27 | C16: =C12-C14 -> 841.66 | D16: =D12-D14 -> 1193.66 | E16: =E12-E14 -> 1421.3 | F16: =F12-F14 -> 1753.7 | G16: =G12-G14 -> 1330.61 | H16: =H12-H14 -> 2004 | I16: =I12-I14 -> 3000.34 | ... K16: =K12-K14 -> 3624.94
A17: % of Sales | B17: =B16/B4 -> 0.06596808 | C17: =C16/C4 -> 0.07073962 | D17: =D16/D4 -> 0.079402648 | E17: =E16/E4 -> 0.071047238 | F17: =F16/F4 -> 0.070514676 | G17: =G16/G4 -> 0.055113698 | H17: =H16/H4 -> 0.064695248 | I17: =I16/I4 -> 0.070035948 | ... K17: =K16/K4 -> 0.061069106
A18: Other income | B18: ='Data sheet'!B22 -> 17.02 | C18: ='Data sheet'!C22 -> 27.7 | D18: ='Data sheet'!D22 -> 87.75 | E18: ='Data sheet'!E22 -> 48.33 | F18: ='Data sheet'!F22 -> 59.99 | G18: ='Data sheet'!G22 -> 194.43 | H18: ='Data sheet'!H22 -> 113.64 | I18: ='Data sheet'!I22 -> 127.6 | ... K18: ='Data sheet'!K22 -> 117.13
A19: Interest | B19: ='Data sheet'!B24 -> 91.34 | C19: ='Data sheet'!C24 -> 121.98 | D19: ='Data sheet'!D24 -> 59.54 | E19: ='Data sheet'!E24 -> 47.21 | F19: ='Data sheet'!F24 -> 69.12 | G19: ='Data sheet'!G24 -> 41.65 | H19: ='Data sheet'!H24 -> 53.79 | I19: ='Data sheet'!I24 -> 67.41 | ... K19: ='Data sheet'!K24 -> 69.45
A20: % of Debt | B20: =B19/SUM('Raw BS'!D7:D10) -> 0.076627517 | C20: =C19/SUM('Raw BS'!E7:E10) -> 0.081428571 | D20: =D19/SUM('Raw BS'!F7:F10) -> 0.13562642 | E20: =E19/SUM('Raw BS'!G7:G10) -> 0.067442857 | F20: =F19/SUM('Raw BS'!H7:H10) -> 0.20756757 | G20: =G19/SUM('Raw BS'!I7:I10) -> 0.10597964 | H20: =H19/SUM('Raw BS'!J7:J10) -> 0.083137558 | I20: =I19/SUM('Raw BS'!K7:K10) -> 0.1048367 | ... K20: =K19/SUM('Raw BS'!M7:M10) -> 0.084695122
A21: PBT | B21: =B16-B19+B18 -> 491.95 | C21: =C16-C19+C18 -> 747.38 | D21: =D16-D19+D18 -> 1221.87 | E21: =E16-E19+E18 -> 1422.42 | F21: =F16-F19+F18 -> 1744.57 | G21: =G16-G19+G18 -> 1483.39 | H21: =H16-H19+H18 -> 2063.85 | I21: =I16-I19+I18 -> 3060.53 | ... K21: =K16-K19+K18 -> 3672.62
A22: % of Sales | B22: =B21/B4 -> 0.057310112 | C22: =C21/C4 -> 0.062815599 | D22: =D21/D4 -> 0.081279186 | E22: =E21/E4 -> 0.071103224 | F22: =F21/F4 -> 0.070147567 | G22: =G21/G4 -> 0.061441826 | H22: =H21/H4 -> 0.066627389 | I22: =I21/I4 -> 0.071440943 | ... K22: =K21/K4 -> 0.061872368
A23: Tax | B23: ='Data sheet'!B26 -> 171.47 | C23: ='Data sheet'!C26 -> 268.28 | D23: ='Data sheet'!D26 -> 415.79 | E23: ='Data sheet'!E26 -> 519.48 | F23: ='Data sheet'!F26 -> 443.79 | G23: ='Data sheet'!G26 -> 384.02 | H23: ='Data sheet'!H26 -> 571.72 | I23: ='Data sheet'!I26 -> 681.75 | ... K23: ='Data sheet'!K26 -> 965.22
A24: Net profit | B24: =B21-B23 -> 320.48 | C24: =C21-C23 -> 479.1 | D24: =D21-D23 -> 806.08 | E24: =E21-E23 -> 902.94 | F24: =F21-F23 -> 1300.78 | G24: =G21-G23 -> 1099.37 | H24: =H21-H23 -> 1492.13 | I24: =I21-I23 -> 2378.78 | ... K24: =K21-K23 -> 2707.4
A25: % of Sales | B25: =B24/B4 -> 0.037334576 | C25: =C24/C4 -> 0.040267272 | D25: =D24/D4 -> 0.053620701 | E25: =E24/E4 -> 0.045135716 | F25: =F24/F4 -> 0.052303177 | G25: =G24/G4 -> 0.045535766 | H25: =H24/H4 -> 0.048170519 | I25: =I24/I4 -> 0.055527077 | ... K25: =K24/K4 -> 0.045611375
E27: Balance Sheet
A28: Narration | B28: 42460 | C28: 42825 | D28: 43190 | E28: 43555 | F28: 43921 | G28: 44286 | H28: 44651 | I28: 45016 | J28: 45382 | K28: 45747
A29: Equity Share Capital | B29: =IFERROR('Data sheet'!B54,0) -> 561.54 | C29: =IFERROR('Data sheet'!C54,0) -> 624.08 | D29: =IFERROR('Data sheet'!D54,0) -> 624.08 | E29: =IFERROR('Data sheet'!E54,0) -> 624.08 | F29: =IFERROR('Data sheet'!F54,0) -> 647.77 | G29: =IFERROR('Data sheet'!G54,0) -> 647.77 | H29: =IFERROR('Data sheet'!H54,0) -> 647.77 | I29: =IFERROR('Data sheet'!I54,0) -> 648.26 | ... K29: =IFERROR('Data sheet'!K54,0) -> 650.73
A30: Reserves | B30: =IFERROR('Data sheet'!B55,0) -> 958.9 | C30: =IFERROR('Data sheet'!C55,0) -> 3217.7 | D30: =IFERROR('Data sheet'!D55,0) -> 4044.97 | E30: =IFERROR('Data sheet'!E55,0) -> 4963.37 | F30: =IFERROR('Data sheet'!F55,0) -> 10431.97 | G30: =IFERROR('Data sheet'!G55,0) -> 11535.94 | H30: =IFERROR('Data sheet'!H55,0) -> 13029.87 | I30: =IFERROR('Data sheet'!I55,0) -> 15430.44 | ... K30: =IFERROR('Data sheet'!K55,0) -> 20777.02
A31: Borrowings | B31: =IFERROR('Data sheet'!B56,0) -> 1192.34 | C31: =IFERROR('Data sheet'!C56,0) -> 1497.32 | D31: =IFERROR('Data sheet'!D56,0) -> 439.25 | E31: =IFERROR('Data sheet'!E56,0) -> 700.15 | F31: =IFERROR('Data sheet'!F56,0) -> 333.19 | G31: =IFERROR('Data sheet'!G56,0) -> 392.71 | H31: =IFERROR('Data sheet'!H56,0) -> 646.94 | I31: =IFERROR('Data sheet'!I56,0) -> 642.98 | ... K31: =IFERROR('Data sheet'!K56,0) -> 819.62
A32: Other Liabilities | B32: =IFERROR('Data sheet'!B57,0) -> 388.78 | C32: =IFERROR('Data sheet'!C57,0) -> 480.18 | D32: =IFERROR('Data sheet'!D57,0) -> 539.92 | E32: =IFERROR('Data sheet'!E57,0) -> 717.9 | F32: =IFERROR('Data sheet'!F57,0) -> 663.23 | G32: =IFERROR('Data sheet'!G57,0) -> 1078.63 | H32: =IFERROR('Data sheet'!H57,0) -> 1146.4 | I32: =IFERROR('Data sheet'!I57,0) -> 1382.84 | ... K32: =IFERROR('Data sheet'!K57,0) -> 2065.41
A33: Total Liabilities | B33: =IFERROR('Data sheet'!B58,0) -> 3101.56 | C33: =IFERROR('Data sheet'!C58,0) -> 5819.28 | D33: =IFERROR('Data sheet'!D58,0) -> 5648.22 | E33: =IFERROR('Data sheet'!E58,0) -> 7005.5 | F33: =IFERROR('Data sheet'!F58,0) -> 12076.16 | G33: =IFERROR('Data sheet'!G58,0) -> 13655.05 | H33: =IFERROR('Data sheet'!H58,0) -> 15470.98 | I33: =IFERROR('Data sheet'!I58,0) -> 18104.52 | ... K33: =IFERROR('Data sheet'!K58,0) -> 24312.78
A35: Fixed Assets Net Block | B35: =IFERROR('Data sheet'!B59,0) -> 2093.52 | C35: =IFERROR('Data sheet'!C59,0) -> 2577.75 | D35: =IFERROR('Data sheet'!D59,0) -> 3399.97 | E35: =IFERROR('Data sheet'!E59,0) -> 4400.37 | F35: =IFERROR('Data sheet'!F59,0) -> 5948.03 | G35: =IFERROR('Data sheet'!G59,0) -> 7008.8 | H35: =IFERROR('Data sheet'!H59,0) -> 9260.02 | I35: =IFERROR('Data sheet'!I59,0) -> 11340.48 | ... K35: =IFERROR('Data sheet'!K59,0) -> 16206.46
A36: Capital Work in Progress | B36: =IFERROR('Data sheet'!B60,0) -> 81.69 | C36: =IFERROR('Data sheet'!C60,0) -> 152.89 | D36: =IFERROR('Data sheet'!D60,0) -> 147.07 | E36: =IFERROR('Data sheet'!E60,0) -> 376.84 | F36: =IFERROR('Data sheet'!F60,0) -> 364.4 | G36: =IFERROR('Data sheet'!G60,0) -> 1019.59 | H36: =IFERROR('Data sheet'!H60,0) -> 1129.34 | I36: =IFERROR('Data sheet'!I60,0) -> 829.16 | ... K36: =IFERROR('Data sheet'!K60,0) -> 1099.35
A37: Investments | B37: =IFERROR('Data sheet'!B61,0) -> 29.33 | C37: =IFERROR('Data sheet'!C61,0) -> 25.69 | D37: =IFERROR('Data sheet'!D61,0) -> 68.18 | E37: =IFERROR('Data sheet'!E61,0) -> 16.53 | F37: =IFERROR('Data sheet'!F61,0) -> 14.68 | G37: =IFERROR('Data sheet'!G61,0) -> 2.95 | H37: =IFERROR('Data sheet'!H61,0) -> 5.94 | I37: =IFERROR('Data sheet'!I61,0) -> 202.2 | ... K37: =IFERROR('Data sheet'!K61,0) -> 3.26
A38: Other Assets | B38: =IFERROR('Data sheet'!B62-SUM('Data sheet'!B64:B66),0) -> 181.81 | C38: =IFERROR('Data sheet'!C62-SUM('Data sheet'!C64:C66),0) -> 209.76 | D38: =IFERROR('Data sheet'!D62-SUM('Data sheet'!D64:D66),0) -> 275.85 | E38: =IFERROR('Data sheet'!E62-SUM('Data sheet'!E64:E66),0) -> 319.67 | F38: =IFERROR('Data sheet'!F62-SUM('Data sheet'!F64:F66),0) -> 3674.22 | G38: =IFERROR('Data sheet'!G62-SUM('Data sheet'!G64:G66),0) -> 1886.27 | H38: =IFERROR('Data sheet'!H62-SUM('Data sheet'!H64:H66),0) -> 1967.55 | I38: =IFERROR('Data sheet'!I62-SUM('Data sheet'!I64:I66),0) -> 1018.71 | ... K38: =IFERROR('Data sheet'!K62-SUM('Data sheet'!K64:K66),0) -> 1447.35
A39: Total Non Current Assets | B39: =SUM(B35:B38) -> 2386.35 | C39: =SUM(C35:C38) -> 2966.09 | D39: =SUM(D35:D38) -> 3891.07 | E39: =SUM(E35:E38) -> 5113.41 | F39: =SUM(F35:F38) -> 10001.33 | G39: =SUM(G35:G38) -> 9917.61 | H39: =SUM(H35:H38) -> 12362.85 | I39: =SUM(I35:I38) -> 13390.55 | ... K39: =SUM(K35:K38) -> 18756.42
A41: Receivables | B41: =IFERROR('Data sheet'!B64,0) -> 8.42 | C41: =IFERROR('Data sheet'!C64,0) -> 21 | D41: =IFERROR('Data sheet'!D64,0) -> 33.52 | E41: =IFERROR('Data sheet'!E64,0) -> 64.37 | F41: =IFERROR('Data sheet'!F64,0) -> 19.55 | G41: =IFERROR('Data sheet'!G64,0) -> 43.58 | H41: =IFERROR('Data sheet'!H64,0) -> 66.89 | I41: =IFERROR('Data sheet'!I64,0) -> 62.16 | ... K41: =IFERROR('Data sheet'!K64,0) -> 153.79
A42: Inventory | B42: =IFERROR('Data sheet'!B65,0) -> 671.69 | C42: =IFERROR('Data sheet'!C65,0) -> 947.9 | D42: =IFERROR('Data sheet'!D65,0) -> 1163.45 | E42: =IFERROR('Data sheet'!E65,0) -> 1608.65 | F42: =IFERROR('Data sheet'!F65,0) -> 1947.4 | G42: =IFERROR('Data sheet'!G65,0) -> 2248.28 | H42: =IFERROR('Data sheet'!H65,0) -> 2742.66 | I42: =IFERROR('Data sheet'!I65,0) -> 3243.48 | ... K42: =IFERROR('Data sheet'!K65,0) -> 5044.37
A43: Cash & Bank | B43: =IFERROR('Data sheet'!B66,0) -> 35.1 | C43: =IFERROR('Data sheet'!C66,0) -> 1884.29 | D43: =IFERROR('Data sheet'!D66,0) -> 560.18 | E43: =IFERROR('Data sheet'!E66,0) -> 219.07 | F43: =IFERROR('Data sheet'!F66,0) -> 107.88 | G43: =IFERROR('Data sheet'!G66,0) -> 1445.58 | H43: =IFERROR('Data sheet'!H66,0) -> 298.58 | I43: =IFERROR('Data sheet'!I66,0) -> 1408.33 | ... K43: =IFERROR('Data sheet'!K66,0) -> 358.2
...

Sheet Data sheet
A1: COMPANY NAME | B1: AVENUE SUPERMARTS LTD | E1: =IF(B2<>B3, "A NEW VERSION OF THE WORKSHEET IS AVAILABLE", "")
A2: LATEST VERSION | B2: 2.1 | E2: PLEASE DO NOT MAKE ANY CHANGES TO THIS SHEET
A3: CURRENT VERSION | B3: 2.1
A5: META
A6: Number of shares | B6: =IF(B9>0, B9/B8, 0) -> 65.20883
A7: Face Value | B7: 10
A8: Current Price | B8: 4530 | D8: Data based on Apr 30,2026
A9: Market Capitalization | B9: 295396
A12: PROFIT & LOSS
A13: Report Date | B13: 42460 | C13: 42825 | D13: 43190 | E13: 43555 | F13: 43921 | G13: 44286 | H13: 44651 | I13: 45016 | J13: 45382 | K13: 45747
A14: Sales | B14: 8583.76 | C14: 11897.7 | D14: 15033.2 | E14: 20004.52 | F14: 24870.2 | G14: 24143.06 | H14: 30976.27 | I14: 42839.56 | J14: 50788.83 | K14: 59358.05
A15: Raw Material Cost | B15: 7435.62 | C15: 10357.25 | D15: 12846.95 | E15: 17445.49 | F15: 21441.68 | G15: 20855.56 | H15: 26891.77 | I15: 36884.77 | J15: 43958.31 | K15: 51668.76
A16: Change in Inventory | B16: 132.08 | C16: 276.22 | D16: 211.31 | E16: 444.65 | F16: 338.75 | G16: 300.88 | H16: 494.38 | I16: 500.82 | J16: 683.77 | K16: 1117.06
A17: Power and Fuel | B17: 79.24 | C17: 99.41 | D17: 121.26 | E17: 152.8 | F17: 188.24 | G17: 174.2 | H17: 207.86 | I17: 314.62 | J17: 376.59 | K17: 447.75
A18: Other Mfr. Exp | B18: 241.36 | C18: 332.9 | D18: 373.72 | E18: 499.72 | F18: 645.96 | G18: 746.43 | H18: 805.85 | I18: 1116.56 | J18: 1323.43 | K18: 1751.85
A19: Employee Cost | B19: 149.04 | C19: 192.67 | D19: 283.14 | E19: 356.17 | F19: 457.14 | G19: 537.58 | H19: 617.36 | I19: 748.16 | J19: 907.82 | K19: 1167.47
A20: Selling and admin | B20: 647.37 | C20: 71.24 | D20: 96 | E20: 135.84 | F20: 66.4 | G20: 108.69 | H20: 143.41 | I20: 212.04 | J20: 274.43 | K20: 312.48
A21: Other Expenses | B21: -501.25 | C21: 151.27 | D21: 170.58 | E21: 225.84 | F21: 281.22 | G21: 276.65 | H21: 302.05 | I21: 425.46 | J21: 526.38 | K21: 632.29
A22: Other Income | B22: 17.02 | C22: 27.7 | D22: 87.75 | E22: 48.33 | F22: 59.99 | G22: 194.43 | H22: 113.64 | I22: 127.6 | J22: 144.58 | K22: 117.13
A23: Depreciation | B23: 98.43 | C23: 127.82 | D23: 159 | E23: 212.49 | F23: 374.41 | G23: 414.16 | H23: 498.08 | I23: 638.87 | J23: 730.76 | K23: 869.52
A24: Interest | B24: 91.34 | C24: 121.98 | D24: 59.54 | E24: 47.21 | F24: 69.12 | G24: 41.65 | H24: 53.79 | I24: 67.41 | J24: 58.13 | K24: 69.45
... A27: Net profit | B27: 320.24 | C27: 478.75 | D27: 806.26 | E27: 902.54 | F27: 1301.08 | G27: 1099.49 | H27: 1492.55 | I27: 2378.51 | J27: 2536.17 | K27: 2708.02
A28: Dividend Amount
A29: Effective Tax Rate | B29: =B26/B25 -> 0.34872181 | C29: =C26/C25 -> 0.35910478 | D29: =D26/D25 -> 0.34023419 | E29: =E26/E25 -> 0.36533187 | F29: =F26/F25 -> 0.25435444 | G29: =G26/G25 -> 0.25886953 | H29: =H26/H25 -> 0.27698002 | I29: =I26/I25 -> 0.22278757 | ... K29: =K26/K25 -> 0.26281152
A31: EBITDA | B31: =+B27+B26+B24+B23 -> 681.48 | C31: =+C27+C26+C24+C23 -> 996.83 | D31: =+D27+D26+D24+D23 -> 1440.59 | E31: =+E27+E26+E24+E23 -> 1681.72 | F31: =+F27+F26+F24+F23 -> 2188.4 | G31: =+G27+G26+G24+G23 -> 1939.32 | H31: =+H27+H26+H24+H23 -> 2616.14 | I31: =+I27+I26+I24+I23 -> 3766.54 | ... K31: =+K27+K26+K24+K23 -> 4612.21
A33: EPS | B33: 5.7 | C33: 7.67 | D33: 12.92 | E33: 14.46 | F33: 20.09 | G33: 16.97 | H33: 23.04 | I33: 36.69 | J33: 38.97 | K33: 41.61
B35: =B14-SUM(B15:B21) -> 400.3
A37: Quarters
A38: Report Date | B38: 45199 | C38: 45291 | D38: 45382 | E38: 45473 | F38: 45565 | G38: 45657 | H38: 45747 | I38: 45838 | J38: 45930 | K38: 46022
A39: Sales | B39: 12624.37 | C39: 13572.47 | D39: 12726.55 | E39: 14069.14 | F39: 14444.5 | G39: 15972.55 | H39: 14871.86 | I39: 16359.7 | J39: 16676.3 | K39: 18100.88
A40: Expenses | B40: 11619.4 | C40: 12452.58 | D40: 11782.91 | E40: 12847.89 | F40: 13350.73 | G40: 14755.31 | H40: 13916.79 | I40: 15060.66 | J40: 15462.65 | K40: 16637.51
A41: Other Income | B41: 36.92 | C41: 32.92 | D41: 37.87 | E41: 41.6 | F41: 33.52 | G41: 24.14 | H41: 25.05 | I41: 19.43 | J41: 19.57 | K41: 16.93
A42: Depreciation | B42: 174.36 | C42: 189.33 | D42: 204.89 | E42: 192.76 | F42: 207.78 | G42: 228.12 | H42: 240.86 | I42: 231.7 | J42: 253.47 | K42: 268.29
A43: Interest | B43: 15.59 | C43: 14.55 | D43: 13.42 | E43: 15.96 | F43: 16.32 | G43: 18.21 | H43: 18.96 | I43: 29.3 | J43: 34.96 | K43: 36.82
A44: Profit before tax | B44: 851.94 | C44: 948.93 | D44: 763.2 | E44: 1054.13 | F44: 903.19 | G44: 995.05 | H44: 720.3 | I44: 1057.47 | J44: 944.79 | K44: 1175.19
A45: Tax | B45: 228.59 | C45: 258.52 | D45: 200.06 | E45: 280.45 | F45: 243.75 | G45: 271.51 | H45: 169.51 | I45: 284.66 | J45: 259.94 | K45: 319.41
A46: Net profit | B46: 623.56 | C46: 690.61 | D46: 563.25 | E46: 773.82 | F46: 659.58 | G46: 723.72 | H46: 550.9 | I46: 772.97 | J46: 685.01 | K46: 855.92
A47: Operating Profit | B47: 1004.97 | C47: 1119.89 | D47: 943.64 | E47: 1221.25 | F47: 1093.77 | G47: 1217.24 | H47: 955.07 | I47: 1299.04 | J47: 1213.65 | K47: 1463.37
A48: EBITDA | B48: =B46+B45+B43+B42 -> 1042.1 | C48: =C46+C45+C43+C42 -> 1153.01 | D48: =D46+D45+D43+D42 -> 981.62 | E48: =E46+E45+E43+E42 -> 1262.99 | F48: =F46+F45+F43+F42 -> 1127.43 | G48: =G46+G45+G43+G42 -> 1241.56 | H48: =H46+H45+H43+H42 -> 980.23 | I48: =I46+I45+I43+I42 -> 1318.63 | ... K48: =K46+K45+K43+K42 -> 1480.44
A52: BALANCE SHEET
...

Sheet Raw BS
A1: Balance sheet
A2: Particulars | B2: 41699 | C2: 42064 | D2: 42430 | E2: 42795 | F2: 43160 | G2: 43525 | H2: 43891 | I2: 44256 | J2: 44621 | K2: 44986 | L2: 45352 | M2: 45717
A4: Equity Capital | B4: 547 | C4: 562 | D4: 562 | E4: 624 | F4: 624 | G4: 624 | H4: 648 | I4: 648 | J4: 648 | K4: 648 | L4: 651 | M4: 651
A5: Reserves | B5: 409 | C5: 638 | D5: 959 | E5: 3218 | F5: 4045 | G5: 4963 | H5: 10432 | I5: 11536 | J5: 13030 | K5: 15430 | L5: 18047 | M5: 20777
A6: Borrowings -
A7: Long term Borrowings | D7: 908 | E7: 981 | F7: 246 | G7: 126 | H7: 0 | I7: 0 | J7: 0 | K7: 0 | L7: 0 | M7: 0
A8: Short term Borrowings | D8: 129 | E8: 139 | F8: 7 | G8: 304 | H8: 4 | I8: 0 | J8: 0 | K8: 0 | L8: 0 | M8: 0
A9: Lease Liabilities | D9: 0 | E9: 0 | F9: 0 | G9: 0 | H9: 295 | I9: 393 | J9: 647 | K9: 643 | L9: 592 | M9: 820
A10: Other Borrowings | B10: 641 | C10: 904 | D10: 155 | E10: 378 | F10: 186 | G10: 270 | H10: 34 | I10: 0 | J10: 0 | K10: 0 | L10: 0 | M10: 0
A11: Other Liabilities -
A12: Non controlling int | B12: 0 | C12: 0 | D12: 0 | E12: 0 | F12: 1 | G12: 1 | H12: 0 | I12: 0 | J12: 0 | K12: 0 | L12: 0 | M12: -1
A13: Trade Payables | B13: 123 | C13: 119 | D13: 194 | E13: 261 | F13: 317 | G13: 463 | H13: 433 | I13: 578 | J13: 589 | K13: 754 | L13: 985 | M13: 1071
A14: Other liability items | B14: 89 | C14: 133 | D14: 194 | E14: 219 | F14: 222 | G14: 254 | H14: 229 | I14: 500 | J14: 557 | K14: 629 | L14: 898 | M14: 996
A15: Total Liabilities | B15: 1808 | C15: 2355 | D15: 3102 | E15: 5819 | F15: 5648 | G15: 7006 | H15: 12076 | I15: 13655 | J15: 15471 | K15: 18105 | L15: 21172 | M15: 24313
A17: Fixed Assets - | B17: 1172 | C17: 1528 | D17: 2094 | E17: 2578 | F17: 3400 | G17: 4400 | H17: 5948 | I17: 7009 | J17: 9260 | K17: 11340 | L17: 13415 | M17: 16206
A18: Land | B18: 460 | C18: 602 | D18: 784 | E18: 1044 | F18: 1438 | G18: 2028 | H18: 2740 | I18: 3483 | J18: 4527 | K18: 5519 | L18: 6904 | M18: 8595
A19: Building | B19: 717 | C19: 946 | D19: 1162 | E19: 1379 | F19: 1757 | G19: 2173 | H19: 3139 | I19: 3649 | J19: 4938 | K19: 6201 | L19: 7062 | M19: 8256
A20: Plant Machinery | B20: 39 | C20: 51 | D20: 59 | E20: 88 | F20: 124 | G20: 191 | H20: 272 | I20: 352 | J20: 491 | K20: 656 | L20: 870 | M20: 1141
A21: Equipments | B21: 9 | C21: 12 | D21: 11 | E21: 16 | F21: 21 | G21: 29 | H21: 39 | I21: 50 | J21: 73 | K21: 85 | L21: 97 | M21: 115
A22: Computers | B22: 23 | C22: 30 | D22: 21 | E22: 30 | F22: 53 | G22: 76 | H22: 95 | I22: 119 | J22: 153 | K22: 190 | L22: 219 | M22: 276
A23: Furniture n fittings | B23: 135 | C23: 172 | D23: 143 | E23: 202 | F23: 265 | G23: 357 | H23: 476 | I23: 581 | J23: 772 | K23: 968 | L23: 1205 | M23: 1515
A24: Vehicles | B24: 4 | C24: 6 | D24: 6 | E24: 6 | F24: 2 | G24: 3 | H24: 4 | I24: 4 | J24: 3 | K24: 15 | L24: 17 | M24: 6
... A28: Accumulated Depreciation | B28: 225 | C28: 304 | D28: 98 | E28: 228 | F28: 401 | G28: 609 | H28: 979 | I28: 1387 | J28: 1867 | K28: 2476 | L28: 3156 | M28: 3900
A29: Net Block | B29: =B27-B28 -> 1172 | C29: =C27-C28 -> 1528 | D29: =D27-D28 -> 2094 | E29: =E27-E28 -> 2577 | F29: =F27-F28 -> 3400 | G29: =G27-G28 -> 4401 | H29: =H27-H28 -> 5948 | I29: =I27-I28 -> 7009 | ... M29: =M27-M28 -> 16206
A31: CWIP | B31: 89 | C31: 98 | D31: 82 | E31: 153 | F31: 147 | G31: 377 | H31: 364 | I31: 1020 | J31: 1129 | K31: 829 | L31: 935 | M31: 1099
A32: Investments | B32: 16 | C32: 15 | D32: 29 | E32: 26 | F32: 68 | G32: 17 | H32: 15 | I32: 3 | J32: 6 | K32: 202 | L32: 107 | M32: 3
A34: Other Assets -
A35: Inventories | B35: 378 | C35: 540 | D35: 672 | E35: 948 | F35: 1163 | G35: 1609 | H35: 1947 | I35: 2248 | J35: 2743 | K35: 3243 | L35: 3927 | M35: 5044
A36: Trade receivables | B36: 10 | C36: 7 | D36: 8 | E36: 21 | F36: 34 | G36: 64 | H36: 20 | I36: 44 | J36: 67 | K36: 62 | L36: 166 | M36: 154
A37: Cash Equivalents | B37: 55 | C37: 38 | D37: 35 | E37: 1884 | F37: 560 | G37: 219 | H37: 108 | I37: 1446 | J37: 299 | K37: 1408 | L37: 638 | M37: 358
A38: Loans n Advances | B38: 14 | C38: 21 | D38: 32 | E38: 45 | F38: 51 | G38: 98 | H38: 101 | I38: 81 | J38: 109 | K38: 97 | L38: 105 | M38: 126
A39: Other asset items | B39: 74 | C39: 108 | D39: 150 | E39: 165 | F39: 225 | G39: 221 | H39: 3574 | I39: 1806 | J39: 1859 | K39: 922 | L39: 1879 | M39: 1321
A40: Total Assets | B40: 1808 | C40: 2355 | D40: 3102 | E40: 5819 | F40: 5648 | G40: 7006 | H40: 12076 | I40: 13655 | J40: 15471 | K40: 18105 | L40: 21172 | M40: 24313

Sheet Raw cashflow
A1: Cash Flows
B2: 41699 | C2: 42064 | D2: 42430 | E2: 42795 | F2: 43160 | G2: 43525 | H2: 43891 | I2: 44256 | J2: 44621 | K2: 44986 | L2: 45352 | M2: 45717
A3: Cash from Operating Activity - | B3: 198 | C3: 222 | D3: 433 | E3: 455 | F3: 730 | G3: 807 | H3: 1280 | I3: 1375 | J3: 1372 | K3: 2630 | L3: 2746 | M3: 2463
A4: Profit from operations | B4: 356 | C4: 474 | D4: 666 | E4: 984 | F4: 1375 | G4: 1659 | H4: 2149 | I4: 1764 | J4: 2515 | K4: 3659 | L4: 4131 | M4: 4535
A5: Receivables | B5: 4 | C5: 2 | D5: -1 | E5: 54 | F5: -13 | G5: -31 | H5: 45 | I5: -24 | J5: -23 | K5: 5 | L5: -104 | M5: 13
A6: Inventory | B6: -102 | C6: -161 | D6: -132 | E6: -276 | F6: -212 | G6: -445 | H6: -339 | I6: -301 | J6: -494 | K6: -501 | L6: -684 | M6: -1117
A7: Payables | B7: 28 | C7: -4 | D7: 72 | E7: 0 | F7: 55 | G7: 146 | H7: -30 | I7: 145 | J7: 11 | K7: 165 | L7: 231 | M7: 86
A8: Loans Advances | B8: -18 | C8: -5 | D8: 0 | E8: 0 | F8: 0 | G8: 0 | H8: 0 | I8: 0 | J8: 0 | K8: 0 | L8: 0 | M8: 0
A9: Operating investments | B9: 0 | C9: 0 | D9: 0 | E9: -2 | F9: -62 | G9: 52 | H9: 2 | I9: 12 | J9: -3 | K9: 0 | L9: 0 | M9: 0
A10: Other WC items | B10: 6 | C10: 16 | D10: -7 | E10: -46 | F10: -11 | G10: -72 | H10: -54 | I10: 41 | J10: -73 | K10: 12 | L10: -87 | M10: -94
A11: Working capital changes | B11: -83 | C11: -152 | D11: -69 | E11: -270 | F11: -243 | G11: -351 | H11: -376 | I11: -127 | J11: -582 | K11: -320 | L11: -644 | M11: -1113
A12: Direct taxes | B12: -75 | C12: -100 | D12: -164 | E12: -258 | F12: -403 | G12: -502 | H12: -492 | I12: -262 | J12: -560 | K12: -709 | L12: -742 | M12: -959
A13: Cash from Investing Activity - | B13: -270 | C13: -474 | D13: -633 | E13: -2482 | F13: 464 | G13: -958 | H13: -4657 | I13: -1110 | J13: -1289 | K13: -2313 | L13: -2468 | M13: -2185
A14: Fixed assets purchased | B14: -272 | C14: -477 | D14: 0 | E14: -645 | F14: -916 | G14: -1417 | H14: -1712 | I14: -2029 | J14: -2410 | K14: -2212 | L14: -2731 | M14: -3423
... A36: CFO/OP | B36: 0.8 | C36: 0.71 | D36: 0.9 | E36: 0.74 | F36: 0.84 | G36: 0.8 | H36: 0.83 | I36: 0.94 | J36: 0.77 | K36: 0.92 | L36: 0.85 | M36: 0.76
